<?xml version="1.0"?>

<robot xmlns:xacro="http://www.ros.org/wiki/xacro">

    <xacro:include filename="$(find zoomlet_description)/urdf/properties.xacro" />

    <xacro:property name="BASE_LENGTH" value="0.6" />
    <xacro:property name="BASE_WIDTH" value="0.4" />
    <xacro:property name="BASE_HEIGHT" value="0.2" />

    <xacro:property name="WHEEL_RADIUS" value="0.1" />
    <xacro:property name="WHEEL_LENGTH" value="0.05" />

    <xacro:property name="BASE_MASS" value="3.5" />
    <xacro:property name="WHEEL_MASS" value="0.3" />
    <xacro:property name="CASTER_MASS" value="0.2" />

    <!-- MACRO: Wheel -->
    <xacro:macro name="wheel_link" params="prefix">
        <link name="${prefix}_wheel_link">
            <visual>
                <geometry>
                    <cylinder radius="${WHEEL_RADIUS}" length="${WHEEL_LENGTH}" />
                </geometry>
                <origin xyz="0.0 0.0 0.0" rpy="${-pi / 2.0} 0.0 0.0" />
                <material name="red" />
            </visual>

            <collision>
                <geometry>
                    <cylinder radius="${WHEEL_RADIUS}" length="${WHEEL_LENGTH}" />
                </geometry>
                <origin xyz="0.0 0.0 0.0" rpy="${-pi / 2.0} 0.0 0.0" />
            </collision>

            <xacro:cylinder_inertia m="${WHEEL_MASS}" r="${INERTIA_MULTIPLY * WHEEL_RADIUS}"
                h="${INERTIA_MULTIPLY * WHEEL_LENGTH}"
                xyz="0.0 0.0 0.0" rpy="${-pi / 2.0} 0.0 0.0" />
        </link>
    </xacro:macro>


    <!-- Base link -->
    <link name="base_link">
        <visual>
            <geometry>
                <box size="${BASE_LENGTH} ${BASE_WIDTH} ${BASE_HEIGHT} " />
            </geometry>
            <origin xyz="0 0 ${BASE_HEIGHT/2.0}" rpy="0 0 0" />
            <material name="blue" />
        </visual>

        <collision>
            <geometry>
                <box size="${BASE_LENGTH} ${BASE_WIDTH} ${BASE_HEIGHT} " />
            </geometry>
            <origin xyz="0 0 ${BASE_HEIGHT/2.0}" rpy="0 0 0" />
        </collision>

        <xacro:box_inertia m="${BASE_MASS}" l="${INERTIA_MULTIPLY * BASE_LENGTH}"
            w="${INERTIA_MULTIPLY * BASE_WIDTH}" h="${INERTIA_MULTIPLY * BASE_HEIGHT}"
            xyz="0 0 ${BASE_HEIGHT/2.0}" rpy="0 0 0" />
    </link>

    <!-- Wheels links-->
    <xacro:wheel_link prefix="right" />
    <xacro:wheel_link prefix="left" />

    <link name="caster_wheel_link">
        <visual>
            <geometry>
                <sphere radius="${WHEEL_RADIUS / 2.0}" />
            </geometry>
            <origin xyz="0.0 0.0 0" rpy="0.0 0.0 0.0" />
            <material name="red" />
        </visual>

        <collision>
            <geometry>
                <sphere radius="${WHEEL_RADIUS / 2.0}" />
            </geometry>
            <origin xyz="0.0 0.0 0" rpy="0.0 0.0 0.0" />
        </collision>

        <xacro:sphere_inertia m="${CASTER_MASS}" r="${INERTIA_MULTIPLY * WHEEL_RADIUS / 2.0}"
            xyz="0.0 0.0 0"
            rpy="0.0 0.0 0.0" />
    </link>

    <!-- Wheels joints -->
    <joint name="base_right_wheel_joint" type="continuous">
        <parent link="base_link" />
        <child link="right_wheel_link" />
        <origin xyz="${-BASE_LENGTH/4} ${-(BASE_WIDTH + WHEEL_LENGTH) / 2.0 } 0.0" rpy="0.0 0.0 0.0" />
        <axis xyz="0.0 1 0.0" />
    </joint>

    <joint name="base_left_wheel_joint" type="continuous">
        <parent link="base_link" />
        <child link="left_wheel_link" />
        <origin xyz="${-BASE_LENGTH/4} ${(BASE_WIDTH + WHEEL_LENGTH) / 2.0} 0.0" rpy="0.0 0.0 0.0" />
        <axis xyz="0.0 1 0.0" />
    </joint>

    <joint name="base_caster_wheel_joint" type="fixed">
        <parent link="base_link" />
        <child link="caster_wheel_link" />
        <origin xyz="${BASE_LENGTH / 3.0} 0.0 ${-WHEEL_RADIUS / 2.0}" rpy="0.0 0.0 0.0" />
    </joint>

</robot>
